Workbook

Sheet top_500_ai_firms
A1: firm_name
A2: International Business Machines Corporation
A3: MICROSOFT TECHNOLOGY LICENSING, LLC
A4: Google LLC
A5: AMAZON TECHNOLOGIES, INC.
A6: Intel Corporation
A7: Apple Inc.
A8: Oracle International Corporation
A9: QUALCOMM Incorporated
A10: AT&T Intellectual Property I, L.P.
A11: EMC IP Holding Company LLC
A12: FACEBOOK, INC.
... A501: Kepler Computing Inc.

Sheet filtered us listed company
A1: original_patent_file_name | B1: company_name | C1: standard company name | D1: LLC/INC | E1: ticker | F1: Exchange
A2: {=XLOOKUP(TRUE,ISNUMBER(SEARCH(B2,top_500_ai_firms!A:A)),top_500_ai_firms!A:A,"")} -> International Business Machines Corporation | B2: International Business Machines Corporation | C2: International Business Machines Corporation (IBM) | E2: IBM | F2: NYSE
A3: {=XLOOKUP(TRUE,ISNUMBER(SEARCH(B3,top_500_ai_firms!A:A)),top_500_ai_firms!A:A,"")} -> MICROSOFT TECHNOLOGY LICENSING, LLC | B3: MICROSOFT TECHNOLOGY LICENSING | C3: Microsoft Corporation | D3: LLC | E3: MSFT | F3: NASDAQ
A4: {=XLOOKUP(TRUE,ISNUMBER(SEARCH(B4,top_500_ai_firms!A:A)),top_500_ai_firms!A:A,"")} -> Google LLC | B4: Google LLC | C4: Alphabet Inc. (Google) | E4: GOOGL | F4: NASDAQ
A5: {=XLOOKUP(TRUE,ISNUMBER(SEARCH(B5,top_500_ai_firms!A:A)),top_500_ai_firms!A:A,"")} -> AMAZON TECHNOLOGIES, INC. | B5: AMAZON TECHNOLOGIES | C5: Amazon Technologies, Inc. | D5: INC. | E5: AMZN | F5: NASDAQ
A6: {=XLOOKUP(TRUE,ISNUMBER(SEARCH(B6,top_500_ai_firms!A:A)),top_500_ai_firms!A:A,"")} -> Intel Corporation | B6: Intel Corporation | C6: Intel Corporation | E6: INTC | F6: NASDAQ
A7: {=XLOOKUP(TRUE,ISNUMBER(SEARCH(B7,top_500_ai_firms!A:A)),top_500_ai_firms!A:A,"")} -> Apple Inc. | B7: Apple Inc. | C7: Apple Inc. | E7: AAPL | F7: NASDAQ
A8: {=XLOOKUP(TRUE,ISNUMBER(SEARCH(B8,top_500_ai_firms!A:A)),top_500_ai_firms!A:A,"")} -> Oracle International Corporation | B8: Oracle International Corporation | C8: Oracle Corporation | E8: ORCL | F8: NYSE
A9: {=XLOOKUP(TRUE,ISNUMBER(SEARCH(B9,top_500_ai_firms!A:A)),top_500_ai_firms!A:A,"")} -> QUALCOMM Incorporated | B9: QUALCOMM Incorporated | C9: QUALCOMM Incorporated | E9: QCOM | F9: NASDAQ
A10: {=XLOOKUP(TRUE,ISNUMBER(SEARCH(B10,top_500_ai_firms!A:A)),top_500_ai_firms!A:A,"")} -> FACEBOOK, INC. | B10: FACEBOOK | C10: Meta Platforms, Inc. | D10: INC. | E10: META | F10: NASDAQ
A11: {=XLOOKUP(TRUE,ISNUMBER(SEARCH(B11,top_500_ai_firms!A:A)),top_500_ai_firms!A:A,"")} -> Bank of America Corporation | B11: Bank of America Corporation | C11: Bank of America Corporation | E11: BAC | F11: NYSE
A12: {=XLOOKUP(TRUE,ISNUMBER(SEARCH(B12,top_500_ai_firms!A:A)),top_500_ai_firms!A:A,"")} -> Cisco Technology, Inc. | B12: Cisco Technology | C12: Cisco Systems, Inc. | D12: Inc. | E12: CSCO | F12: NASDAQ
A13: {=XLOOKUP(TRUE,ISNUMBER(SEARCH(B13,top_500_ai_firms!A:A)),top_500_ai_firms!A:A,"")} -> CAPITAL ONE SERVICES, LLC | B13: CAPITAL ONE SERVICES | C13: Capital One Financial Corporation | D13: LLC | E13: COF | F13: NYSE
A14: {=XLOOKUP(TRUE,ISNUMBER(SEARCH(B14,top_500_ai_firms!A:A)),top_500_ai_firms!A:A,"")} -> Micron Technology, Inc. | B14: Micron Technology | C14: Micron Technology, Inc. | D14: Inc. | E14: MU | F14: NASDAQ
A15: {=XLOOKUP(TRUE,ISNUMBER(SEARCH(B15,top_500_ai_firms!A:A)),top_500_ai_firms!A:A,"")} -> Ford Global Technologies, LLC | B15: Ford Global Technologies | C15: Ford Motor Company | D15: LLC | E15: F | F15: NYSE
A16: {=XLOOKUP(TRUE,ISNUMBER(SEARCH(B16,top_500_ai_firms!A:A)),top_500_ai_firms!A:A,"")} -> General Electric Company | B16: General Electric Company | C16: GE Vernova Inc. / GE Aerospace (formerly General Electric Company) | E16: GEV | F16: NYSE
A17: {=XLOOKUP(TRUE,ISNUMBER(SEARCH(B17,top_500_ai_firms!A:A)),top_500_ai_firms!A:A,"")} -> Adobe Inc. | B17: Adobe Inc. | C17: Adobe Inc. | E17: ADBE | F17: NASDAQ
A18: {=XLOOKUP(TRUE,ISNUMBER(SEARCH(B18,top_500_ai_firms!A:A)),top_500_ai_firms!A:A,"")} -> Salesforce.com, Inc. | B18: Salesforce.com | C18: Salesforce, Inc. | D18: Inc. | E18: CRM | F18: NYSE
A19: {=XLOOKUP(TRUE,ISNUMBER(SEARCH(B19,top_500_ai_firms!A:A)),top_500_ai_firms!A:A,"")} -> The Boeing Company | B19: The Boeing Company | C19: The Boeing Company | E19: BA | F19: NYSE
A20: {=XLOOKUP(TRUE,ISNUMBER(SEARCH(B20,top_500_ai_firms!A:A)),top_500_ai_firms!A:A,"")} -> Verizon Patent and Licensing Inc. | B20: Verizon Patent and Licensing Inc. | C20: Verizon Communications Inc. | E20: VZ | F20: NYSE
A21: {=XLOOKUP(TRUE,ISNUMBER(SEARCH(B21,top_500_ai_firms!A:A)),top_500_ai_firms!A:A,"")} -> HONEYWELL INTERNATIONAL INC. | B21: HONEYWELL INTERNATIONAL INC. | C21: Honeywell International Inc. | E21: HON | F21: NASDAQ
A22: {=XLOOKUP(TRUE,ISNUMBER(SEARCH(B22,top_500_ai_firms!A:A)),top_500_ai_firms!A:A,"")} -> Hewlett Packard Enterprise Development LP | B22: Hewlett Packard Enterprise Development LP | C22: Hewlett Packard Enterprise Company | E22: HPE | F22: NYSE
A23: {=XLOOKUP(TRUE,ISNUMBER(SEARCH(B23,top_500_ai_firms!A:A)),top_500_ai_firms!A:A,"")} -> GM GLOBAL TECHNOLOGY OPERATIONS LLC | B23: GM GLOBAL TECHNOLOGY OPERATIONS LLC | C23: General Motors Company | E23: GM | F23: NYSE
A24: {=XLOOKUP(TRUE,ISNUMBER(SEARCH(B24,top_500_ai_firms!A:A)),top_500_ai_firms!A:A,"")} -> eBay Inc. | B24: eBay Inc. | C24: eBay Inc. | E24: EBAY | F24: NASDAQ
A25: {=XLOOKUP(TRUE,ISNUMBER(SEARCH(B25,top_500_ai_firms!A:A)),top_500_ai_firms!A:A,"")} -> SNAP INC. | B25: SNAP INC. | C25: Snap Inc. | E25: SNAP | F25: NYSE
A26: {=XLOOKUP(TRUE,ISNUMBER(SEARCH(B26,top_500_ai_firms!A:A)),top_500_ai_firms!A:A,"")} -> PAYPAL, INC. | B26: PAYPAL | C26: PayPal Holdings, Inc. | D26: INC. | E26: PYPL | F26: NASDAQ
A27: {=XLOOKUP(TRUE,ISNUMBER(SEARCH(B27,top_500_ai_firms!A:A)),top_500_ai_firms!A:A,"")} -> Intuit Inc. | B27: Intuit Inc. | C27: Intuit Inc. | E27: INTU | F27: NASDAQ
A28: {=XLOOKUP(TRUE,ISNUMBER(SEARCH(B28,top_500_ai_firms!A:A)),top_500_ai_firms!A:A,"")} -> TEXAS INSTRUMENTS INCORPORATED | B28: TEXAS INSTRUMENTS INCORPORATED | C28: Texas Instruments Incorporated | E28: TXN | F28: NASDAQ
A29: {=XLOOKUP(TRUE,ISNUMBER(SEARCH(B29,top_500_ai_firms!A:A)),top_500_ai_firms!A:A,"")} -> NVIDIA Corporation | B29: NVIDIA Corporation | C29: NVIDIA Corporation | E29: NVDA | F29: NASDAQ
A30: {=XLOOKUP(TRUE,ISNUMBER(SEARCH(B30,top_500_ai_firms!A:A)),top_500_ai_firms!A:A,"")} -> Palantir Technologies Inc. | B30: Palantir Technologies Inc. | C30: Palantir Technologies Inc. | E30: PLTR | F30: NYSE
A31: {=XLOOKUP(TRUE,ISNUMBER(SEARCH(B31,top_500_ai_firms!A:A)),top_500_ai_firms!A:A,"")} -> Advanced Micro Devices, Inc. | B31: Advanced Micro Devices | C31: Advanced Micro Devices, Inc. (AMD) | D31: Inc. | E31: AMD | F31: NASDAQ
A32: {=XLOOKUP(TRUE,ISNUMBER(SEARCH(B32,top_500_ai_firms!A:A)),top_500_ai_firms!A:A,"")} -> Adobe Systems Incorporated | B32: Adobe Systems Incorporated | C32: Adobe Inc. | E32: ADBE | F32: NASDAQ
A33: {=XLOOKUP(TRUE,ISNUMBER(SEARCH(B33,top_500_ai_firms!A:A)),top_500_ai_firms!A:A,"")} -> ServiceNow, Inc. | B33: ServiceNow | C33: ServiceNow, Inc. | D33: Inc. | E33: NOW | F33: NYSE
A34: {=XLOOKUP(TRUE,ISNUMBER(SEARCH(B34,top_500_ai_firms!A:A)),top_500_ai_firms!A:A,"")} -> Xerox Corporation | B34: Xerox Corporation | C34: Xerox Holdings Corporation | E34: XRX | F34: NASDAQ
A35: {=XLOOKUP(TRUE,ISNUMBER(SEARCH(B35,top_500_ai_firms!A:A)),top_500_ai_firms!A:A,"")} -> Juniper Networks, Inc. | B35: Juniper Networks | C35: Juniper Networks, Inc. | D35: Inc. | E35: JNPR | F35: NYSE
A36: {=XLOOKUP(TRUE,ISNUMBER(SEARCH(B36,top_500_ai_firms!A:A)),top_500_ai_firms!A:A,"")} -> GoPro, Inc. | B36: GoPro | C36: GoPro, Inc. | D36: Inc. | E36: GPRO | F36: NASDAQ
A37: {=XLOOKUP(TRUE,ISNUMBER(SEARCH(B37,top_500_ai_firms!A:A)),top_500_ai_firms!A:A,"")} -> Facebook Technologies, LLC | B37: Facebook Technologies | C37: Meta Platforms, Inc. | D37: LLC | E37: META | F37: NASDAQ
A38: {=XLOOKUP(TRUE,ISNUMBER(SEARCH(B38,top_500_ai_firms!A:A)),top_500_ai_firms!A:A,"")} -> T-Mobile USA, Inc. | B38: T-Mobile USA | C38: T-Mobile US, Inc. | D38: Inc. | E38: TMUS | F38: NASDAQ
A39: {=XLOOKUP(TRUE,ISNUMBER(SEARCH(B39,top_500_ai_firms!A:A)),top_500_ai_firms!A:A,"")} -> Western Digital Technologies, Inc. | B39: Western Digital Technologies | C39: Western Digital Corporation | D39: Inc. | E39: WDC | F39: NASDAQ
A40: {=XLOOKUP(TRUE,ISNUMBER(SEARCH(B40,top_500_ai_firms!A:A)),top_500_ai_firms!A:A,"")} -> Uber Technologies, Inc. | B40: Uber Technologies | C40: Uber Technologies, Inc. | D40: Inc. | E40: UBER | F40: NYSE
...
